Workbook

Sheet Build Configurator
A1: Build Configurator
A2: Pick a preset to fill every value below, then type over any SPECIAL or Rank cell to customize it — typing a number replaces that one cell's formula without affecting the rest. SPECIAL and Rank are whole-number inputs (1-15 and 0-3 respectively); 'Valid?' flags a rank that exceeds a perk's real max.
A4: Preset: | B4: Atom - Ghoul VATS/Onslaught/Cripple
A6: SPECIAL
A7: SPECIAL | B7: Value | C7: Points Used | D7: Free Points | E7: Status
A8: STR | B8: =VLOOKUP($B$4,Presets!$A$5:$IQ$6,2,FALSE) | C8: =SUMIF($A$19:$A$261,A8,$F$19:$F$261) | D8: =B8-C8 | E8: =IF(D8<0,"OVER-ALLOCATED",IF(D8=0,"Fully allocated","Points free"))
A9: PER | B9: =VLOOKUP($B$4,Presets!$A$5:$IQ$6,3,FALSE) | C9: =SUMIF($A$19:$A$261,A9,$F$19:$F$261) | D9: =B9-C9 | E9: =IF(D9<0,"OVER-ALLOCATED",IF(D9=0,"Fully allocated","Points free"))
A10: END | B10: =VLOOKUP($B$4,Presets!$A$5:$IQ$6,4,FALSE) | C10: =SUMIF($A$19:$A$261,A10,$F$19:$F$261) | D10: =B10-C10 | E10: =IF(D10<0,"OVER-ALLOCATED",IF(D10=0,"Fully allocated","Points free"))
A11: CHA | B11: =VLOOKUP($B$4,Presets!$A$5:$IQ$6,5,FALSE) | C11: =SUMIF($A$19:$A$261,A11,$F$19:$F$261) | D11: =B11-C11 | E11: =IF(D11<0,"OVER-ALLOCATED",IF(D11=0,"Fully allocated","Points free"))
A12: INT | B12: =VLOOKUP($B$4,Presets!$A$5:$IQ$6,6,FALSE) | C12: =SUMIF($A$19:$A$261,A12,$F$19:$F$261) | D12: =B12-C12 | E12: =IF(D12<0,"OVER-ALLOCATED",IF(D12=0,"Fully allocated","Points free"))
A13: AGI | B13: =VLOOKUP($B$4,Presets!$A$5:$IQ$6,7,FALSE) | C13: =SUMIF($A$19:$A$261,A13,$F$19:$F$261) | D13: =B13-C13 | E13: =IF(D13<0,"OVER-ALLOCATED",IF(D13=0,"Fully allocated","Points free"))
A14: LCK | B14: =VLOOKUP($B$4,Presets!$A$5:$IQ$6,8,FALSE) | C14: =SUMIF($A$19:$A$261,A14,$F$19:$F$261) | D14: =B14-C14 | E14: =IF(D14<0,"OVER-ALLOCATED",IF(D14=0,"Fully allocated","Points free"))
A17: Perks
A18: SPECIAL | B18: Perk | C18: Rank | D18: Max Rank | E18: Valid? | F18: Point Cost | G18: Current Value | H18: Bucket | I18: Notes
A19: STR | B19: Arms Keeper | C19: =VLOOKUP($B$4,Presets!$A$5:$IQ$6,9,FALSE) | D19: =INDEX('Perk Values'!$C$5:$C$247,MATCH($B19,'Perk Values'!$A$5:$A$247,0)) | E19: =IF(C19<=D19,"OK","exceeds max rank "&D19) | F19: =INDEX('Perk Values'!$G$5:$K$247,MATCH($B19,'Perk Values'!$A$5:$A$247,0),C19+1) | G19: =INDEX('Perk Values'!$L$5:$P$247,MATCH($B19,'Perk Values'!$A$5:$A$247,0),C19+1) | H19: =INDEX('Perk Values'!$D$5:$D$247,MATCH($B19,'Perk Values'!$A$5:$A$247,0))
A20: STR | B20: Bandolier | C20: =VLOOKUP($B$4,Presets!$A$5:$IQ$6,10,FALSE) | D20: =INDEX('Perk Values'!$C$5:$C$247,MATCH($B20,'Perk Values'!$A$5:$A$247,0)) | E20: =IF(C20<=D20,"OK","exceeds max rank "&D20) | F20: =INDEX('Perk Values'!$G$5:$K$247,MATCH($B20,'Perk Values'!$A$5:$A$247,0),C20+1) | G20: =INDEX('Perk Values'!$L$5:$P$247,MATCH($B20,'Perk Values'!$A$5:$A$247,0),C20+1) | H20: =INDEX('Perk Values'!$D$5:$D$247,MATCH($B20,'Perk Values'!$A$5:$A$247,0))
A21: STR | B21: Barbarian | C21: =VLOOKUP($B$4,Presets!$A$5:$IQ$6,11,FALSE) | D21: =INDEX('Perk Values'!$C$5:$C$247,MATCH($B21,'Perk Values'!$A$5:$A$247,0)) | E21: =IF(C21<=D21,"OK","exceeds max rank "&D21) | F21: =INDEX('Perk Values'!$G$5:$K$247,MATCH($B21,'Perk Values'!$A$5:$A$247,0),C21+1) | G21: =INDEX('Perk Values'!$L$5:$P$247,MATCH($B21,'Perk Values'!$A$5:$A$247,0),C21+1) | H21: =INDEX('Perk Values'!$D$5:$D$247,MATCH($B21,'Perk Values'!$A$5:$A$247,0))
A22: STR | B22: Basher | C22: =VLOOKUP($B$4,Presets!$A$5:$IQ$6,12,FALSE) | D22: =INDEX('Perk Values'!$C$5:$C$247,MATCH($B22,'Perk Values'!$A$5:$A$247,0)) | E22: =IF(C22<=D22,"OK","exceeds max rank "&D22) | F22: =INDEX('Perk Values'!$G$5:$K$247,MATCH($B22,'Perk Values'!$A$5:$A$247,0),C22+1) | G22: =INDEX('Perk Values'!$L$5:$P$247,MATCH($B22,'Perk Values'!$A$5:$A$247,0),C22+1) | H22: =INDEX('Perk Values'!$D$5:$D$247,MATCH($B22,'Perk Values'!$A$5:$A$247,0))
A23: STR | B23: Bear Arms | C23: =VLOOKUP($B$4,Presets!$A$5:$IQ$6,13,FALSE) | D23: =INDEX('Perk Values'!$C$5:$C$247,MATCH($B23,'Perk Values'!$A$5:$A$247,0)) | E23: =IF(C23<=D23,"OK","exceeds max rank "&D23) | F23: =INDEX('Perk Values'!$G$5:$K$247,MATCH($B23,'Perk Values'!$A$5:$A$247,0),C23+1) | G23: =INDEX('Perk Values'!$L$5:$P$247,MATCH($B23,'Perk Values'!$A$5:$A$247,0),C23+1) | H23: =INDEX('Perk Values'!$D$5:$D$247,MATCH($B23,'Perk Values'!$A$5:$A$247,0))
A24: STR | B24: Blocker | C24: =VLOOKUP($B$4,Presets!$A$5:$IQ$6,14,FALSE) | D24: =INDEX('Perk Values'!$C$5:$C$247,MATCH($B24,'Perk Values'!$A$5:$A$247,0)) | E24: =IF(C24<=D24,"OK","exceeds max rank "&D24) | F24: =INDEX('Perk Values'!$G$5:$K$247,MATCH($B24,'Perk Values'!$A$5:$A$247,0),C24+1) | G24: =INDEX('Perk Values'!$L$5:$P$247,MATCH($B24,'Perk Values'!$A$5:$A$247,0),C24+1) | H24: =INDEX('Perk Values'!$D$5:$D$247,MATCH($B24,'Perk Values'!$A$5:$A$247,0))
A25: STR | B25: Blood Luster | C25: =VLOOKUP($B$4,Presets!$A$5:$IQ$6,15,FALSE) | D25: =INDEX('Perk Values'!$C$5:$C$247,MATCH($B25,'Perk Values'!$A$5:$A$247,0)) | E25: =IF(C25<=D25,"OK","exceeds max rank "&D25) | F25: =INDEX('Perk Values'!$G$5:$K$247,MATCH($B25,'Perk Values'!$A$5:$A$247,0),C25+1) | G25: =INDEX('Perk Values'!$L$5:$P$247,MATCH($B25,'Perk Values'!$A$5:$A$247,0),C25+1) | H25: =INDEX('Perk Values'!$D$5:$D$247,MATCH($B25,'Perk Values'!$A$5:$A$247,0))
A26: STR | B26: Bringing the Big Guns | C26: =VLOOKUP($B$4,Presets!$A$5:$IQ$6,16,FALSE) | D26: =INDEX('Perk Values'!$C$5:$C$247,MATCH($B26,'Perk Values'!$A$5:$A$247,0)) | E26: =IF(C26<=D26,"OK","exceeds max rank "&D26) | F26: =INDEX('Perk Values'!$G$5:$K$247,MATCH($B26,'Perk Values'!$A$5:$A$247,0),C26+1) | G26: =INDEX('Perk Values'!$L$5:$P$247,MATCH($B26,'Perk Values'!$A$5:$A$247,0),C26+1) | H26: =INDEX('Perk Values'!$D$5:$D$247,MATCH($B26,'Perk Values'!$A$5:$A$247,0))
A27: STR | B27: Bullet Storm | C27: =VLOOKUP($B$4,Presets!$A$5:$IQ$6,17,FALSE) | D27: =INDEX('Perk Values'!$C$5:$C$247,MATCH($B27,'Perk Values'!$A$5:$A$247,0)) | E27: =IF(C27<=D27,"OK","exceeds max rank "&D27) | F27: =INDEX('Perk Values'!$G$5:$K$247,MATCH($B27,'Perk Values'!$A$5:$A$247,0),C27+1) | G27: =INDEX('Perk Values'!$L$5:$P$247,MATCH($B27,'Perk Values'!$A$5:$A$247,0),C27+1) | H27: =INDEX('Perk Values'!$D$5:$D$247,MATCH($B27,'Perk Values'!$A$5:$A$247,0))
A28: STR | B28: Easy Target | C28: =VLOOKUP($B$4,Presets!$A$5:$IQ$6,18,FALSE) | D28: =INDEX('Perk Values'!$C$5:$C$247,MATCH($B28,'Perk Values'!$A$5:$A$247,0)) | E28: =IF(C28<=D28,"OK","exceeds max rank "&D28) | F28: =INDEX('Perk Values'!$G$5:$K$247,MATCH($B28,'Perk Values'!$A$5:$A$247,0),C28+1) | G28: =INDEX('Perk Values'!$L$5:$P$247,MATCH($B28,'Perk Values'!$A$5:$A$247,0),C28+1) | H28: =INDEX('Perk Values'!$D$5:$D$247,MATCH($B28,'Perk Values'!$A$5:$A$247,0))
A29: STR | B29: Full Charge | C29: =VLOOKUP($B$4,Presets!$A$5:$IQ$6,19,FALSE) | D29: =INDEX('Perk Values'!$C$5:$C$247,MATCH($B29,'Perk Values'!$A$5:$A$247,0)) | E29: =IF(C29<=D29,"OK","exceeds max rank "&D29) | F29: =INDEX('Perk Values'!$G$5:$K$247,MATCH($B29,'Perk Values'!$A$5:$A$247,0),C29+1) | G29: =INDEX('Perk Values'!$L$5:$P$247,MATCH($B29,'Perk Values'!$A$5:$A$247,0),C29+1) | H29: =INDEX('Perk Values'!$D$5:$D$247,MATCH($B29,'Perk Values'!$A$5:$A$247,0))
A30: STR | B30: Heavy Hitter | C30: =VLOOKUP($B$4,Presets!$A$5:$IQ$6,20,FALSE) | D30: =INDEX('Perk Values'!$C$5:$C$247,MATCH($B30,'Perk Values'!$A$5:$A$247,0)) | E30: =IF(C30<=D30,"OK","exceeds max rank "&D30) | F30: =INDEX('Perk Values'!$G$5:$K$247,MATCH($B30,'Perk Values'!$A$5:$A$247,0),C30+1) | G30: =INDEX('Perk Values'!$L$5:$P$247,MATCH($B30,'Perk Values'!$A$5:$A$247,0),C30+1) | H30: =INDEX('Perk Values'!$D$5:$D$247,MATCH($B30,'Perk Values'!$A$5:$A$247,0))
A31: STR | B31: Incisor | C31: =VLOOKUP($B$4,Presets!$A$5:$IQ$6,21,FALSE) | D31: =INDEX('Perk Values'!$C$5:$C$247,MATCH($B31,'Perk Values'!$A$5:$A$247,0)) | E31: =IF(C31<=D31,"OK","exceeds max rank "&D31) | F31: =INDEX('Perk Values'!$G$5:$K$247,MATCH($B31,'Perk Values'!$A$5:$A$247,0),C31+1) | G31: =INDEX('Perk Values'!$L$5:$P$247,MATCH($B31,'Perk Values'!$A$5:$A$247,0),C31+1) | H31: =INDEX('Perk Values'!$D$5:$D$247,MATCH($B31,'Perk Values'!$A$5:$A$247,0))
A32: STR | B32: Iron Fist | C32: =VLOOKUP($B$4,Presets!$A$5:$IQ$6,22,FALSE) | D32: =INDEX('Perk Values'!$C$5:$C$247,MATCH($B32,'Perk Values'!$A$5:$A$247,0)) | E32: =IF(C32<=D32,"OK","exceeds max rank "&D32) | F32: =INDEX('Perk Values'!$G$5:$K$247,MATCH($B32,'Perk Values'!$A$5:$A$247,0),C32+1) | G32: =INDEX('Perk Values'!$L$5:$P$247,MATCH($B32,'Perk Values'!$A$5:$A$247,0),C32+1) | H32: =INDEX('Perk Values'!$D$5:$D$247,MATCH($B32,'Perk Values'!$A$5:$A$247,0))
A33: STR | B33: Knee-Capper | C33: =VLOOKUP($B$4,Presets!$A$5:$IQ$6,23,FALSE) | D33: =INDEX('Perk Values'!$C$5:$C$247,MATCH($B33,'Perk Values'!$A$5:$A$247,0)) | E33: =IF(C33<=D33,"OK","exceeds max rank "&D33) | F33: =INDEX('Perk Values'!$G$5:$K$247,MATCH($B33,'Perk Values'!$A$5:$A$247,0),C33+1) | G33: =INDEX('Perk Values'!$L$5:$P$247,MATCH($B33,'Perk Values'!$A$5:$A$247,0),C33+1) | H33: =INDEX('Perk Values'!$D$5:$D$247,MATCH($B33,'Perk Values'!$A$5:$A$247,0))
A34: STR | B34: Lock and Load | C34: =VLOOKUP($B$4,Presets!$A$5:$IQ$6,24,FALSE) | D34: =INDEX('Perk Values'!$C$5:$C$247,MATCH($B34,'Perk Values'!$A$5:$A$247,0)) | E34: =IF(C34<=D34,"OK","exceeds max rank "&D34) | F34: =INDEX('Perk Values'!$G$5:$K$247,MATCH($B34,'Perk Values'!$A$5:$A$247,0),C34+1) | G34: =INDEX('Perk Values'!$L$5:$P$247,MATCH($B34,'Perk Values'!$A$5:$A$247,0),C34+1) | H34: =INDEX('Perk Values'!$D$5:$D$247,MATCH($B34,'Perk Values'!$A$5:$A$247,0))
A35: STR | B35: Love the Spread | C35: =VLOOKUP($B$4,Presets!$A$5:$IQ$6,25,FALSE) | D35: =INDEX('Perk Values'!$C$5:$C$247,MATCH($B35,'Perk Values'!$A$5:$A$247,0)) | E35: =IF(C35<=D35,"OK","exceeds max rank "&D35) | F35: =INDEX('Perk Values'!$G$5:$K$247,MATCH($B35,'Perk Values'!$A$5:$A$247,0),C35+1) | G35: =INDEX('Perk Values'!$L$5:$P$247,MATCH($B35,'Perk Values'!$A$5:$A$247,0),C35+1) | H35: =INDEX('Perk Values'!$D$5:$D$247,MATCH($B35,'Perk Values'!$A$5:$A$247,0))
A36: STR | B36: Martial Artist | C36: =VLOOKUP($B$4,Presets!$A$5:$IQ$6,26,FALSE) | D36: =INDEX('Perk Values'!$C$5:$C$247,MATCH($B36,'Perk Values'!$A$5:$A$247,0)) | E36: =IF(C36<=D36,"OK","exceeds max rank "&D36) | F36: =INDEX('Perk Values'!$G$5:$K$247,MATCH($B36,'Perk Values'!$A$5:$A$247,0),C36+1) | G36: =INDEX('Perk Values'!$L$5:$P$247,MATCH($B36,'Perk Values'!$A$5:$A$247,0),C36+1) | H36: =INDEX('Perk Values'!$D$5:$D$247,MATCH($B36,'Perk Values'!$A$5:$A$247,0))
A37: STR | B37: Natural Stance | C37: =VLOOKUP($B$4,Presets!$A$5:$IQ$6,27,FALSE) | D37: =INDEX('Perk Values'!$C$5:$C$247,MATCH($B37,'Perk Values'!$A$5:$A$247,0)) | E37: =IF(C37<=D37,"OK","exceeds max rank "&D37) | F37: =INDEX('Perk Values'!$G$5:$K$247,MATCH($B37,'Perk Values'!$A$5:$A$247,0),C37+1) | G37: =INDEX('Perk Values'!$L$5:$P$247,MATCH($B37,'Perk Values'!$A$5:$A$247,0),C37+1) | H37: =INDEX('Perk Values'!$D$5:$D$247,MATCH($B37,'Perk Values'!$A$5:$A$247,0))
A38: STR | B38: Ordnance Express | C38: =VLOOKUP($B$4,Presets!$A$5:$IQ$6,28,FALSE) | D38: =INDEX('Perk Values'!$C$5:$C$247,MATCH($B38,'Perk Values'!$A$5:$A$247,0)) | E38: =IF(C38<=D38,"OK","exceeds max rank "&D38) | F38: =INDEX('Perk Values'!$G$5:$K$247,MATCH($B38,'Perk Values'!$A$5:$A$247,0),C38+1) | G38: =INDEX('Perk Values'!$L$5:$P$247,MATCH($B38,'Perk Values'!$A$5:$A$247,0),C38+1) | H38: =INDEX('Perk Values'!$D$5:$D$247,MATCH($B38,'Perk Values'!$A$5:$A$247,0))
A39: STR | B39: Pack Rat | C39: =VLOOKUP($B$4,Presets!$A$5:$IQ$6,29,FALSE) | D39: =INDEX('Perk Values'!$C$5:$C$247,MATCH($B39,'Perk Values'!$A$5:$A$247,0)) | E39: =IF(C39<=D39,"OK","exceeds max rank "&D39) | F39: =INDEX('Perk Values'!$G$5:$K$247,MATCH($B39,'Perk Values'!$A$5:$A$247,0),C39+1) | G39: =INDEX('Perk Values'!$L$5:$P$247,MATCH($B39,'Perk Values'!$A$5:$A$247,0),C39+1) | H39: =INDEX('Perk Values'!$D$5:$D$247,MATCH($B39,'Perk Values'!$A$5:$A$247,0))
A40: STR | B40: Pain Train | C40: =VLOOKUP($B$4,Presets!$A$5:$IQ$6,30,FALSE) | D40: =INDEX('Perk Values'!$C$5:$C$247,MATCH($B40,'Perk Values'!$A$5:$A$247,0)) | E40: =IF(C40<=D40,"OK","exceeds max rank "&D40) | F40: =INDEX('Perk Values'!$G$5:$K$247,MATCH($B40,'Perk Values'!$A$5:$A$247,0),C40+1) | G40: =INDEX('Perk Values'!$L$5:$P$247,MATCH($B40,'Perk Values'!$A$5:$A$247,0),C40+1) | H40: =INDEX('Perk Values'!$D$5:$D$247,MATCH($B40,'Perk Values'!$A$5:$A$247,0))
A41: STR | B41: Portable Power | C41: =VLOOKUP($B$4,Presets!$A$5:$IQ$6,31,FALSE) | D41: =INDEX('Perk Values'!$C$5:$C$247,MATCH($B41,'Perk Values'!$A$5:$A$247,0)) | E41: =IF(C41<=D41,"OK","exceeds max rank "&D41) | F41: =INDEX('Perk Values'!$G$5:$K$247,MATCH($B41,'Perk Values'!$A$5:$A$247,0),C41+1) | G41: =INDEX('Perk Values'!$L$5:$P$247,MATCH($B41,'Perk Values'!$A$5:$A$247,0),C41+1) | H41: =INDEX('Perk Values'!$D$5:$D$247,MATCH($B41,'Perk Values'!$A$5:$A$247,0))
A42: STR | B42: Scattershot | C42: =VLOOKUP($B$4,Presets!$A$5:$IQ$6,32,FALSE) | D42: =INDEX('Perk Values'!$C$5:$C$247,MATCH($B42,'Perk Values'!$A$5:$A$247,0)) | E42: =IF(C42<=D42,"OK","exceeds max rank "&D42) | F42: =INDEX('Perk Values'!$G$5:$K$247,MATCH($B42,'Perk Values'!$A$5:$A$247,0),C42+1) | G42: =INDEX('Perk Values'!$L$5:$P$247,MATCH($B42,'Perk Values'!$A$5:$A$247,0),C42+1) | H42: =INDEX('Perk Values'!$D$5:$D$247,MATCH($B42,'Perk Values'!$A$5:$A$247,0))
A43: STR | B43: Shotgun Champ | C43: =VLOOKUP($B$4,Presets!$A$5:$IQ$6,33,FALSE) | D43: =INDEX('Perk Values'!$C$5:$C$247,MATCH($B43,'Perk Values'!$A$5:$A$247,0)) | E43: =IF(C43<=D43,"OK","exceeds max rank "&D43) | F43: =INDEX('Perk Values'!$G$5:$K$247,MATCH($B43,'Perk Values'!$A$5:$A$247,0),C43+1) | G43: =INDEX('Perk Values'!$L$5:$P$247,MATCH($B43,'Perk Values'!$A$5:$A$247,0),C43+1) | H43: =INDEX('Perk Values'!$D$5:$D$247,MATCH($B43,'Perk Values'!$A$5:$A$247,0))
A44: STR | B44: Slugger | C44: =VLOOKUP($B$4,Presets!$A$5:$IQ$6,34,FALSE) | D44: =INDEX('Perk Values'!$C$5:$C$247,MATCH($B44,'Perk Values'!$A$5:$A$247,0)) | E44: =IF(C44<=D44,"OK","exceeds max rank "&D44) | F44: =INDEX('Perk Values'!$G$5:$K$247,MATCH($B44,'Perk Values'!$A$5:$A$247,0),C44+1) | G44: =INDEX('Perk Values'!$L$5:$P$247,MATCH($B44,'Perk Values'!$A$5:$A$247,0),C44+1) | H44: =INDEX('Perk Values'!$D$5:$D$247,MATCH($B44,'Perk Values'!$A$5:$A$247,0))
...

Sheet Weapon Comparison
A1: Weapon Comparison — sustained DPS, Scenario A vs Scenario B
A2: Set up two weapons (or the same weapon with two different legendary picks) and compare their sustained DPS under one shared combat scenario. Perk-driven numbers come live from 'Build Configurator' — change your build there and both scenarios update. See 'Mechanics & Caps' for what this steady-state model does and doesn't capture.
A4: Shared Combat Scenario
A5: Input | B5: Value
A6: Crippled Limbs on Target (0-4) | B6: 1
A7: Impairment Types on Target (0-5) | B7: 1
A8: Target Bleeding? (Y/N) | B8: N
A9: Target Burning? (Y/N) | B9: N
A10: Onslaught Stacks Right Now (0-30) | B10: 8
A11: Kill-Streak Stacks / Adrenaline (0-10) | B11: 0
A12: Concentrated Fire Stacks (0-20) | B12: 0
A13: Tenderizer Team Stack % Active (0-100) | B13: 0
A14: Enemy Close Range? (Y/N) | B14: N
A15: Distance to Target, feet (gates Down Ranger, 47+) | B15: 60
A16: In VATS, Same-Target Streak? (Y/N) | B16: Y
A17: Weak-Spot Hit Frequency % (0-100) | B17: 70
A18: VATS Critical Frequency % (0-100) | B18: 40
A19: Sneak Attack Frequency % (0-100) | B19: 0
A20: Expending Glow this fight? (Y/N) | B20: Y
A21: Enemy Base Damage Resistance (DR) | B21: 400
A22: Your Max AP Pool | B22: 250
A23: Your AP Regen Rate (per sec) | B23: 14
A25: Build-Derived Values (read-only — from Build Configurator)
A26: Perk | B26: Current Value
A27: Easy Target | B27: ='Build Configurator'!G28
A28: Tormentor | B28: ='Build Configurator'!G88
A29: Tank Killer | B29: ='Build Configurator'!G87
A30: Deal Sealer | B30: ='Build Configurator'!G62
A31: Concentrated Fire | B31: ='Build Configurator'!G60
A32: Number Cruncher | B32: ='Build Configurator'!G78
A33: Gunslinger | B33: ='Build Configurator'!G215
A34: Gunslinger Expert | B34: ='Build Configurator'!G216
A35: Guerrilla | B35: ='Build Configurator'!G210
A36: Guerrilla Expert | B36: ='Build Configurator'!G211
A37: Guerrilla Master | B37: ='Build Configurator'!G212
A38: Adrenaline | B38: ='Build Configurator'!G200
A39: Better Criticals | B39: ='Build Configurator'!G232
A40: Faulty Spots | B40: ='Build Configurator'!G259
A41: Glowing Criticals | B41: ='Build Configurator'!G260
A42: Wild West Hands | B42: ='Build Configurator'!G261
...

Sheet Armor & DR Calculator
A1: Armor & DR Calculator
A2: Fill in your armor's DR per body part (Pip-Boy > Inventory > Apparel). Ironclad and END (for Adamantium Skeleton) come live from 'Build Configurator'. The hit simulator uses the same Damage-Resist formula as Weapon Comparison, run in reverse for incoming hits.
A4: Build-Derived Values (read-only)
A5: Ironclad resistance bonus (current rank) | B5: ='Build Configurator'!G110
A6: Adamantium Skeleton equipped? (1 = yes) | B6: ='Build Configurator'!G93
A7: Your END (for Adamantium Skeleton scaling) | B7: ='Build Configurator'!B10
A8: Adamantium Skeleton limb-DR %, interpolated END1->10% / END15->35% | B8: =IF(B6=1,0.10+(0.35-0.10)/(15-1)*(B7-1),0)
A10: Your Armor, by Body Part
A11: Body Part | B11: Armor Piece DR (input) | C11: 5-Piece Matching Set? (Y/N) | D11: Total Effective DR
A12: Head | B12: 150 | C12: Y | D12: =B12*(1+$B$5*IF(C12="Y",2,1))
A13: Torso | B13: 150 | C13: Y | D13: =B13*(1+$B$5*IF(C13="Y",2,1))
A14: Left Arm | B14: 150 | C14: Y | D14: =B14*(1+$B$5*IF(C14="Y",2,1))
A15: Right Arm | B15: 150 | C15: Y | D15: =B15*(1+$B$5*IF(C15="Y",2,1))
A16: Left Leg | B16: 150 | C16: Y | D16: =B16*(1+$B$5*IF(C16="Y",2,1))
A17: Right Leg | B17: 150 | C17: Y | D17: =B17*(1+$B$5*IF(C17="Y",2,1))
A19: Ironclad and the 5-piece-match doubling come from Build Configurator automatically. Limb-specific armor pieces also benefit from Adamantium Skeleton (B8 above) and any Strengthened/Adamantium legendary mods on that piece — add those manually to this sheet if you use them, since they are per-mod rather than build-wide.
A21: Incoming Hit Simulator
A22: Incoming Raw Damage (input) | B22: 50
A23: Body Part Hit (input) | B23: Torso
A24: Your Effective DR for that Body Part | B24: =VLOOKUP(B23,A12:D17,4,FALSE)
A25: Damage Resist Mult (fraction of the hit that gets through) | B25: =MAX(0.1,MIN(0.99,(B22*0.15/B24)^0.365))
A26: Final Damage Taken | B26: =B22*B25
A27: % of Hit Mitigated | B27: =1-B25

Sheet Perk Cards
A1: Perk Cards — every standard perk card in the game (243), researched Oct 2026
A2: ~30 of these feed live formulas in Weapon Comparison / Armor & DR Calculator (see 'Perk Values' for which). The rest are catalogued for completeness — point cost is still tracked correctly in Build Configurator even for perks that don't move any calculator number.
A4: Perk | B4: SPECIAL | C4: Effect | D4: Values by Rank | E4: Confidence | F4: Source
A5: Arms Keeper | B5: STR | C5: Weapons weigh less | D5: -50% / -75% | E5: Likely | F5: fallout.wiki - Fallout 76 Perks (Strength section)
A6: Bandolier | B6: STR | C6: Ballistic ammo weighs less | D6: -45% / -90% | E6: Likely | F6: fallout.wiki - Fallout 76 Perks (Strength section)
A7: Barbarian | B7: STR | C7: Damage Resistance based on STR, doubled when not wearing armor (non-linear scaling, reworked from old flat +2/3/4 DR per STR in 3 ranks) | D7: ~+18 DR at 1 STR, ~+61 at 15 STR, ~+96 at 30 STR, ~+175 at 100 STR (doubled unarmored); non-linear curve, not a simple per-point multiplier | E7: Likely | F7: fallout.wiki - Barbarian (Fallout 76); cross-checked via WebSearch (post-Update 58 rework)
A8: Basher | B8: STR | C8: Gun bashing deals more damage and limb damage | D8: +25% dmg / +35% limb dmg / +50% dmg / +75% limb dmg | E8: Likely | F8: fallout.wiki - Fallout 76 Perks (Strength section)
A9: Bear Arms | B9: STR | C9: Gun bashing damage increases per Bullet Storm stack | D9: +5% bash damage per Bullet Storm stack | E9: Likely | F9: fallout.wiki - Fallout 76 Perks (Strength section); nukaknights.com Patch 62 changelog
A10: Blocker | B10: STR | C10: Block more incoming melee damage | D10: -15% / -20% / -25% | E10: Likely | F10: fallout.wiki - Fallout 76 Perks (Strength section)
A11: Blood Luster | B11: STR | C11: Bleed effects deal more damage but last less time (formerly Gladiator Master) | D11: +35% bleed damage, -25% bleed duration | E11: Confirmed | F11: nukaknights.com Patch 62 changelog (Gladiator Master -> Blood Luster); fallout.wiki section fetch
A12: Bringing the Big Guns | B12: STR | C12: Doubles the maximum Bullet Storm stack limit (formerly Heavy Gunner Master) | D12: Bullet Storm max stacks doubled (10 -> 20) | E12: Confirmed | F12: nukaknights.com Patch 62 changelog (Heavy Gunner Master -> Bringing the Big Guns)
A13: Bullet Storm | B13: STR | C13: Gain stacking ranged damage per ammo spent (formerly Heavy Gunner); replaces old flat heavy-weapon damage %. Stacks lost on reload or weapon switch | D13: +3% dmg per 30 ammo spent, 10 max stacks / +6% dmg per 30 ammo spent, 10 max stacks / +9% dmg per 30 ammo spent, 10 max stacks | E13: Confirmed | F13: nukaknights.com Patch 62 changelog; fallout.wiki section fetch; WebSearch cross-check
A14: Easy Target | B14: STR | C14: Ranged damage bonus vs crippled targets (formerly Shotgunner) | D14: +25% / +50% / +75% | E14: Confirmed | F14: fallout.wiki - Easy Target (individually verified page); WebSearch cross-check (Shotgunner rename)
A15: Full Charge | B15: STR | C15: Power Armor sprinting uses less Fusion Core energy | D15: -50% drain / no extra drain | E15: Likely | F15: fallout.wiki - Fallout 76 Perks (Strength section)
... A247: Wild West Hands | B247: LCK | C247: Chance for instant magazine reload (Ghoul-exclusive) | D247: 12% / 24% / 36% | E247: Likely | F247: fallout.wiki - Fallout 76 Perks (Ghoul Luck section)

Sheet Legendary Effects
A1: Legendary Effects — weapon and armor mods
A3: Effect | B3: Star | C3: Value | D3: Additive or Multiplicative | E3: Best Use | F3: Confidence | G3: Source
A4: Furious | B4: 1 (weapon) | C4: +5% damage per Onslaught stack you currently have; +9 to your max Onslaught stack cap | D4: Additive (scales with live stack count) | E4: Any build sustaining consecutive hits on one target | F4: Confirmed | G4: Fallout 76 Wiki - Furious/Onslaught
A5: Quad | B5: 1 (weapon) | C5: 4x ammo capacity (e.g. double-barrel shotgun 2→8 shells) | D5: N/A — capacity, not damage | E5: Weapons with very small native magazines | F5: Confirmed | G5: Fallout 76 Wiki
A6: Anti-Armor | B6: 1 (weapon) | C6: +50% armor penetration | D6: Multiplicative with other penetration sources (e.g. Tank Killer) — confirmed this session | E6: One of the strongest general-purpose 1-star picks; competes with Furious/Quad for the same slot | F6: Confirmed | G6: Fallout 76 Wiki - Anti-Armor
A7: Rapid | B7: 2 (weapon) | C7: ~+25% fire rate | D7: Multiplicative (rate of fire, not per-shot damage) | E7: Weapons with ammo/handling headroom to spend on more shots | F7: Confirmed | G7: Fallout 76 Wiki
A8: Vital | B8: 2 (weapon) | C8: +50% critical damage | D8: Additive, into the crit-damage multiplier | E8: VATS crit builds | F8: Confirmed | G8: Fallout 76 Wiki
A9: Explosive | B9: 2 (weapon) | C9: Adds an explosion worth 20% of the weapon's damage | D9: Separate damage instance, not multiplicative with the direct hit | E9: Weapons you want to add AOE chip damage to | F9: Confirmed | G9: Fallout 76 Wiki
A10: Lucky Hit | B10: 3 (weapon) | C10: Increases Critical Meter fill per hit | D10: Resource gain, not damage | E10: Sustained VATS crit builds | F10: Confirmed | G10: Fallout 76 Wiki
A11: V.A.T.S. Optimized | B11: 3 (weapon) | C11: -35% AP cost per VATS shot (~54% more shots per full AP bar) | D11: Multiplicative (AP cost, not damage) | E11: Any VATS-heavy build that is AP-limited rather than ammo/reload-limited | F11: Confirmed | G11: Fallout 76 Wiki
A12: Swift | B12: 3 (weapon) | C12: +15% reload speed | D12: Multiplicative (reload time) | E12: Weapons whose sustained DPS is reload-bottlenecked rather than AP-bottlenecked | F12: Confirmed | G12: Fallout 76 Wiki
A13: Conductor's | B13: 4 (weapon) | C13: On crit: restore 10 HP + 10 AP instantly, plus 100 more of each over 5 sec, to you and teammates within 100 ft | D13: Resource restore — adds no damage | E13: Team play | F13: Confirmed | G13: Fallout 76 Wiki
A14: Pin-Pointer's | B14: 4 (weapon) | C14: +20% weak-spot damage (head and limbs, not torso) | D14: Likely multiplicative with other damage sources | E14: VATS crit / cripple builds | F14: Confirmed value (some older posts cite +50%, outdated/incorrect); Likely multiplicative stacking | G14: Fallout 76 Wiki; player testing
... A29: Weightless | B29: Armor legendary, per piece | C29: -90% weight | D29: N/A | E29: Carry-weight management | F29: Confirmed | G29: Fallout 76 Wiki

Sheet Legendary Perks
A1: Legendary Perks — the Perception-Coin system (distinct from weapon/armor legendary effects)
A2: Slots unlock at character level 50/75/100/150/200/300 (6 slots). Rank 1 of any card is free to equip; ranks 2/3/4 cost 50/100/150 Perk Coins (300 total to max one card). This list covers the SPECIAL perks plus general/Ghoul-only perks verified this session — not a claim every legendary perk in the game is listed.
A4: Perk | B4: SPECIAL | C4: Effect by Rank | D4: Coin Cost (R2/R3/R4) | E4: Confidence | F4: Source
A5: Legendary Strength | B5: STR | C5: +1 / +2 / +3 / +5 STR and matching STR perk-card points (hard cap 15 total) | D5: 50 / 100 / 150 | E5: Confirmed | F5: falloutbuilds.com; Dragonchasers
A6: Legendary Perception | B6: PER | C6: +1 / +2 / +3 / +5 PER and matching PER perk-card points (cap 15) | D6: 50 / 100 / 150 | E6: Confirmed | F6: falloutbuilds.com; Dragonchasers
A7: Legendary Endurance | B7: END | C7: +1 / +2 / +3 / +5 END and matching END perk-card points (cap 15) | D7: 50 / 100 / 150 | E7: Confirmed | F7: falloutbuilds.com; Dragonchasers
A8: Legendary Charisma | B8: CHA | C8: +1 / +2 / +3 / +5 CHA and matching CHA perk-card points (cap 15) | D8: 50 / 100 / 150 | E8: Confirmed | F8: falloutbuilds.com; Dragonchasers
A9: Legendary Intelligence | B9: INT | C9: +1 / +2 / +3 / +5 INT and matching INT perk-card points (cap 15) | D9: 50 / 100 / 150 | E9: Confirmed | F9: falloutbuilds.com; Dragonchasers
A10: Legendary Agility | B10: AGI | C10: +1 / +2 / +3 / +5 AGI and matching AGI perk-card points (cap 15) | D10: 50 / 100 / 150 | E10: Confirmed | F10: falloutbuilds.com; Dragonchasers
A11: Legendary Luck | B11: LCK | C11: +1 / +2 / +3 / +5 LCK and matching LCK perk-card points (cap 15) | D11: 50 / 100 / 150 | E11: Confirmed | F11: falloutbuilds.com; Dragonchasers
A12: Follow Through | B12: General | C12: +10% / 20% / 30% / 40% ranged sneak-attack damage for 10 sec after a sneak attack | D12: 50 / 100 / 150 | E12: Confirmed | F12: timesaver.gg 2026 guide
A13: Master Infiltrator | B13: General | C13: Auto-unlocks locks/terminals up to a skill threshold by rank; +3 Lockpick and Hacking at all ranks | D13: 50 / 100 / 150 | E13: Confirmed | F13: timesaver.gg 2026 guide
A14: Ammo Factory | B14: General | C14: +50% / 75% / 100% / 150% more rounds produced per crafting batch | D14: 50 / 100 / 150 | E14: Confirmed | F14: timesaver.gg 2026 guide
A15: Power Armor Reboot | B15: General | C15: Auto-revive with full health in Power Armor on death; cooldown drops to 8 / 6 / 2 min | D15: 50 / 100 / 150 | E15: Likely | F15: timesaver.gg 2026 guide
... A23: What Rads? | B23: General, Human-only | C23: +50 to +300 Rad Resist; restores 1-6 rads/sec by rank | D23: 50 / 100 / 150 | E23: Confirmed | F23: timesaver.gg 2026 guide

Sheet Mechanics & Caps
A1: Mechanics & Caps — the rules the calculators are built on
A3: Topic | B3: Detail | C3: Confidence | D3: Source
A4: SPECIAL point cap | B4: Each SPECIAL stat can be allocated up to 15 via level-up points (1 point per level, fully respec-able). This is the hard display cap regardless of other bonuses. | C4: Confirmed | D4: Fallout 76 Wiki - SPECIAL; falloutbuilds.com
A5: Legendary SPECIAL perks | B5: 7 legendary perk cards (Legendary Strength/Perception/Endurance/Charisma/Intelligence/Agility/Luck) each add +1/+2/+3/+5 to their SPECIAL stat AND the matching perk-card point budget per rank — but the stat still cannot exceed the 15 cap. | C5: Confirmed | D5: Fallout 76 Wiki - Legendary Perks; Dragonchasers
A6: The '10+5' optimization | B6: Because a maxed (rank 4) Legendary SPECIAL perk adds +5, you only need 10 BASE points in that SPECIAL to reach the 15 cap. Base points invested beyond 10 in a SPECIAL whose matching legendary card is maxed are wasted. | C6: Confirmed | D6: Dragonchasers - Legendary SPECIAL Perks for Newbies
A7: Perk-card point budget | B7: The total point cost of your equipped perk cards under one SPECIAL cannot exceed that SPECIAL's current value. | C7: Confirmed | D7: Fallout 76 Wiki
A8: Legendary perk slots | B8: Legendary perk slots unlock at character level 50, 75, 100, 150, 200 and 300 — 6 slots total. | C8: Confirmed | D8: Fallout 76 Wiki - Legendary Perks
A9: Outgoing damage formula | B9: OutgoingDamage = Base × (1 + ΣDamageBonus) × DamageMult1 × DamageMult2 × ... DamageBonus terms (most perks, mods, chems) ADD together into one bracket; DamageMult terms (sneak attack, critical hit, difficulty, etc.) each multiply the result separately. | C9: Confirmed | D9: Fallout 76 Wiki - Damage
A10: Target resistance formula | B10: DamageResistMult = MAX(0.1, MIN(0.99, (IncomingDamage × 0.15 / Resist) ^ 0.365)). This is the fraction of a hit's damage that gets through: floor 0.1 (at most 90% mitigated), ceiling 0.99 (at least 1% mitigated). | C10: Confirmed | D10: Fallout 76 Wiki - Damage
A11: Armor-penetration stacking | B11: Tank Killer and Anti-Armor both reduce the SAME effective Resist value and stack MULTIPLICATIVELY with each other (confirmed for Anti-Armor x Tank Killer) — so each extra penetration source gives progressively smaller returns once the damage:resist ratio is already high (~6.5:1 reaches the 99%-through ceiling). | C11: Confirmed | D11: Fallout 76 Wiki - Anti-Armor; Fallout 76 Wiki - Damage
A12: Limb health vs. body damage | B12: Limbs carry their own hidden health pool separate from the target's main HP. Perks like Enforcer that boost 'limb damage' increase damage to that hidden pool (crippling the limb faster) and add NO extra damage to the target's main HP — the calculators show this separately, not folded into Sustained DPS. | C12: Confirmed | D12: Fallout 76 Wiki - Enforcer
A13: Weak-spot damage bucket | B13: Weak-spot/limb percentage bonuses (Gunslinger, Gunslinger Expert's per-stack bonus, Pin-Pointer's, Faulty Spots) only apply on a shot that actually lands on a limb or head, never torso, and are believed to sum together before being applied as one extra multiplier on that hit. | C13: Likely | D13: player consensus across multiple build guides
A14: Onslaught | B14: A stacking buff from consecutive hits on the SAME enemy. Each stack decays 1/second once you stop landing hits. Furious converts live stacks into +5% damage per stack and raises the max stack cap by 9; Gunslinger Expert/Guerrilla Expert/Guerrilla Master each add their own stack-cap bonus to the same pool. | C14: Confirmed | D14: Fallout 76 Wiki - Onslaught; Fallout 76 Wiki - Furious
... A21: A second research pass corrected several numbers | B21: Better Criticals was reworked from 20/30/40% to 50/75/100% by patch 1.6.4.60 and this workbook had the stale pre-rework number until a second pass caught it. Glowing Criticals turned out to be 3 ranks (20/35/50%), not a single flat 50%. Ironclad is a clean 15/20/25% per rank (doubled to 30/40/50% with a 5-piece set), not '+15% then +2% per rank after.' Gunslinger Expert, Guerrilla Expert, Guerrilla Master, Awareness, Adrenaline, and Life Giver are each single-rank, higher-point-cost cards, not multi-rank cards — the point cost was already right, only the displayed rank number was corrected. | C21: Confirmed | D21: second independent research pass this session, cross-verified against individual wiki pages

Sheet Perk Values
A1: Perk Values (helper) — rank-indexed numbers the Build Configurator and Weapon Comparison pull from
A2: Edit a perk's values here if a future patch changes it and every calculator updates automatically. 'Bucket' tags which part of the damage/cadence/resistance math a perk feeds; 'non_combat*' buckets are tracked for point-budget purposes only and contribute 0 to every calculator.
A4: Perk | B4: SPECIAL | C4: Max Rank | D4: Bucket | E4: Confidence | F4: Source | G4: Cost R0 | H4: Cost R1 | I4: Cost R2 | J4: Cost R3 | K4: Cost R4 | L4: Value R0 | M4: Value R1 | N4: Value R2 | O4: Value R3 | P4: Value R4
A5: Arms Keeper | B5: STR | C5: 2 | D5: non_combat | E5: Likely | F5: fallout.wiki - Fallout 76 Perks (Strength section) | G5: 0 | H5: 1 | I5: 2 | J5: 2 | K5: 2 | L5: 0 | M5: 0 | N5: 0 | O5: 0 | P5: 0
A6: Bandolier | B6: STR | C6: 2 | D6: non_combat | E6: Likely | F6: fallout.wiki - Fallout 76 Perks (Strength section) | G6: 0 | H6: 1 | I6: 2 | J6: 2 | K6: 2 | L6: 0 | M6: 0 | N6: 0 | O6: 0 | P6: 0
A7: Barbarian | B7: STR | C7: 1 | D7: catalogued_not_wired | E7: Likely | F7: fallout.wiki - Barbarian (Fallout 76); cross-checked via WebSearch (post-Update 58 rework) | G7: 0 | H7: 1 | I7: 1 | J7: 1 | K7: 1 | L7: 0 | M7: 0 | N7: 0 | O7: 0 | P7: 0
A8: Basher | B8: STR | C8: 2 | D8: catalogued_not_wired | E8: Likely | F8: fallout.wiki - Fallout 76 Perks (Strength section) | G8: 0 | H8: 1 | I8: 2 | J8: 2 | K8: 2 | L8: 0 | M8: 0 | N8: 0 | O8: 0 | P8: 0
A9: Bear Arms | B9: STR | C9: 1 | D9: catalogued_not_wired | E9: Likely | F9: fallout.wiki - Fallout 76 Perks (Strength section); nukaknights.com Patch 62 changelog | G9: 0 | H9: 1 | I9: 1 | J9: 1 | K9: 1 | L9: 0 | M9: 0 | N9: 0 | O9: 0 | P9: 0
A10: Blocker | B10: STR | C10: 3 | D10: non_combat_melee_block | E10: Likely | F10: fallout.wiki - Fallout 76 Perks (Strength section) | G10: 0 | H10: 1 | I10: 2 | J10: 3 | K10: 3 | L10: 0 | M10: 0 | N10: 0 | O10: 0 | P10: 0
A11: Blood Luster | B11: STR | C11: 1 | D11: catalogued_not_wired | E11: Confirmed | F11: nukaknights.com Patch 62 changelog (Gladiator Master -> Blood Luster); fallout.wiki section fetch | G11: 0 | H11: 1 | I11: 1 | J11: 1 | K11: 1 | L11: 0 | M11: 0 | N11: 0 | O11: 0 | P11: 0
A12: Bringing the Big Guns | B12: STR | C12: 1 | D12: catalogued_not_wired | E12: Confirmed | F12: nukaknights.com Patch 62 changelog (Heavy Gunner Master -> Bringing the Big Guns) | G12: 0 | H12: 3 | I12: 3 | J12: 3 | K12: 3 | L12: 0 | M12: 0 | N12: 0 | O12: 0 | P12: 0
A13: Bullet Storm | B13: STR | C13: 3 | D13: catalogued_not_wired | E13: Confirmed | F13: nukaknights.com Patch 62 changelog; fallout.wiki section fetch; WebSearch cross-check | G13: 0 | H13: 1 | I13: 2 | J13: 3 | K13: 3 | L13: 0 | M13: 0 | N13: 0 | O13: 0 | P13: 0
A14: Easy Target | B14: STR | C14: 3 | D14: dmg_vs_crippled | E14: Confirmed | F14: fallout.wiki - Easy Target (individually verified page); WebSearch cross-check (Shotgunner rename) (cross-checked this session) | G14: 0 | H14: 1 | I14: 2 | J14: 3 | K14: 3 | L14: 0 | M14: 0.25 | N14: 0.5 | O14: 0.75 | P14: 0
A15: Full Charge | B15: STR | C15: 2 | D15: non_combat | E15: Likely | F15: fallout.wiki - Fallout 76 Perks (Strength section) | G15: 0 | H15: 1 | I15: 2 | J15: 2 | K15: 2 | L15: 0 | M15: 0 | N15: 0 | O15: 0 | P15: 0
A16: Heavy Hitter | B16: STR | C16: 1 | D16: catalogued_not_wired | E16: Confirmed | F16: nukaknights.com Patch 62 changelog (Slugger Master -> Heavy Hitter) | G16: 0 | H16: 3 | I16: 3 | J16: 3 | K16: 3 | L16: 0 | M16: 0 | N16: 0 | O16: 0 | P16: 0
... A247: Wild West Hands | B247: LCK | C247: 3 | D247: reload_reliability_pct | E247: Likely | F247: fallout.wiki - Fallout 76 Perks (Ghoul Luck section) | G247: 0 | H247: 1 | I247: 2 | J247: 3 | K247: 3 | L247: 0 | M247: 0.12 | N247: 0.24 | O247: 0.36 | P247: 0

Sheet Legendary Values
A1: Legendary Values (helper) — bucket-tagged numbers the Weapon Comparison sheet pulls from
A2: Each weapon legendary star slot (1/2/3/4) picks one Effect from this list by name; the Weapon Comparison sheet looks up its Bucket and Value with SUMIFS, so it contributes to the right part of the math automatically. 'per_stack' buckets multiply Value by the live Onslaught-stack input.
A4: Effect | B4: Star | C4: Bucket | D4: Value | E4: Confidence | F4: Source
A5: None | B5: 0 | C5: none | D5: 0 | E5: Confirmed | F5: this workbook
A6: Furious | B6: 1 | C6: dmg_general_per_onslaught_stack | D6: 0.05 | E6: Confirmed | F6: Fallout 76 Wiki - Furious
A7: Quad | B7: 1 | C7: magsize_mult_bonus | D7: 3 | E7: Confirmed | F7: Fallout 76 Wiki (x4 total capacity = +3x)
A8: Anti-Armor | B8: 1 | C8: target_dr_reduction_mult | D8: 0.5 | E8: Confirmed | F8: Fallout 76 Wiki - Anti-Armor
A9: Rapid | B9: 2 | C9: firerate_mult_bonus | D9: 0.25 | E9: Confirmed | F9: Fallout 76 Wiki
A10: Vital | B10: 2 | C10: crit_mult_bonus | D10: 0.5 | E10: Confirmed | F10: Fallout 76 Wiki
A11: Explosive | B11: 2 | C11: explosion_dmg_pct | D11: 0.2 | E11: Confirmed | F11: Fallout 76 Wiki
A12: Lucky Hit | B12: 3 | C12: crit_meter_fill_bonus | D12: 0 | E12: Confirmed | F12: Fallout 76 Wiki (resource only, not modeled numerically)
A13: V.A.T.S. Optimized | B13: 3 | C13: apcost_mult_reduction | D13: 0.35 | E13: Confirmed | F13: Fallout 76 Wiki
A14: Swift | B14: 3 | C14: reload_mult_reduction | D14: 0.15 | E14: Confirmed | F14: Fallout 76 Wiki
A15: Conductor's | B15: 4 | C15: resource_restore_only | D15: 0 | E15: Confirmed | F15: Fallout 76 Wiki (adds no damage)
A16: Pin-Pointer's | B16: 4 | C16: dmg_weakspot | D16: 0.2 | E16: Confirmed | F16: Fallout 76 Wiki
... A22: Encircler's | B22: 4 | C22: dmg_general_flat_bonus | D22: 0.5 | E22: Confirmed | F22: Fallout 76 Wiki (at max nearby-enemy count; scales down with fewer enemies)

Sheet Presets
A1: Presets (helper) — named builds; pick one from the dropdown on Build Configurator
A2: Add a new row here (Preset Name + SPECIAL + a rank per perk) to save another build as a loadable preset.
A4: Preset Name | B4: STR | C4: PER | D4: END | E4: CHA | F4: INT | G4: AGI | H4: LCK | I4: Arms Keeper | J4: Bandolier | K4: Barbarian | L4: Basher | M4: Bear Arms | N4: Blocker | O4: Blood Luster | P4: Bringing the Big Guns | Q4: Bullet Storm | R4: Easy Target | S4: Full Charge | T4: Heavy Hitter | U4: Incisor | V4: Iron Fist | W4: Knee-Capper | X4: Lock and Load | Y4: Love the Spread | Z4: Martial Artist | AA4: Natural Stance | AB4: Ordnance Express | AC4: Pack Rat | AD4: Pain Train | AE4: Portable Power | AF4: Scattershot | AG4: Shotgun Champ | AH4: Slugger | AI4: Strong Arm | AJ4: Strong Back | AK4: Sturdy Frame | AL4: Tightly Wound | AM4: Traveling Pharmacy | AN4: Wound Salter | AO4: Wrecking Ball | AP4: Arms of Steel | AQ4: Bone Shatterer | AR4: Brick Wall | AS4: Radioactive Strength | AT4: Awareness | AU4: Bow Before Me | AV4: Butcher's Bounty | AW4: Center Masochist | AX4: Concentrated Fire | AY4: Crack Shot | AZ4: Deal Sealer | BA4: Down Ranger | BB4: Expert Picklock | BC4: Exterminator | BD4: Fast Fighter | BE4: Fortune Finder | BF4: Glow Sight | BG4: Green Thumb | BH4: Grenadier | BI4: Ground Pounder | BJ4: Hat Trick | BK4: Long Shot | BL4: Master Archer | BM4: Master Picklock | BN4: Night Eyes | BO4: Night Person | BP4: Number Cruncher | BQ4: Pannapictagraphist | BR4: Percepti-Bobble | BS4: Picklock | BT4: Refractor | BU4: Scoped-up | BV4: Skeet Shooter | BW4: Smart Shot | BX4: Sniper | BY4: Tank Killer | BZ4: Tormentor | CA4: Breathe It In | CB4: Eye of the Hunter | CC4: Glowing Hunter | CD4: Rad-Reaver | CE4: Adamantium Skeleton | CF4: All Night Long | CG4: Aquaboy | CH4: Aquagirl | CI4: Bloodsucker | CJ4: Bullet Shield | CK4: Cannibal | CL4: Chem Fiend | CM4: Chem Resistant | CN4: Cola Nut | CO4: Dromedary | CP4: Ghoulish | CQ4: Good Doggy | CR4: Hardy | CS4: Homebody | CT4: Hydro Fix | CU4: Iron Stomach | CV4: Ironclad | CW4: Lead Belly | CX4: Life Giver | CY4: Munchy Resistance | CZ4: Natural Resistance | DA4: Nocturnal Fortitude | DB4: Photosynthetic | DC4: Professional Drinker | DD4: Rad Resistant | DE4: Radicool | DF4: Rejuvenated | DG4: Slow Metabolizer | DH4: Solar Powered | DI4: Starched Genes | DJ4: Sun Kissed | DK4: Thirst Quencher | DL4: Thru-hiker | DM4: Vaccinated | DN4: Rad Sponge | DO4: Chem Diet | DP4: Glowing Gut | DQ4: Radiation Power | DR4: Thick Skin | DS4: Animal Friend | DT4: Anti-Epidemic | DU4: Bodyguards | DV4: E.M.T. | DW4: Friendly Fire | DX4: Happy Camper | DY4: Happy-Go-Lucky | DZ4: Hard Bargain | EA4: Healing Hands | EB4: Injector | EC4: Inspirational | ED4: Lone Wanderer | EE4: Magnetic Personality | EF4: Overly Generous | EG4: Party Boy | EH4: Party Girl | EI4: Philanthropist | EJ4: Quack Surgeon | EK4: Revenant | EL4: Spiritual Healer | EM4: Squad Maneuvers | EN4: Strange In Numbers | EO4: Suppressor | EP4: Team Medic | EQ4: Tenderizer | ER4: Travel Agent | ES4: Wasteland Whisperer | ET4: Feral Presence | EU4: Glowing One | EV4: Moral Support | EW4: United Ordeal | EX4: Armorer | EY4: Batteries Included | EZ4: Chemist | FA4: Contractor | FB4: Cryologist | FC4: Curator | FD4: Demolition Expert | FE4: Expert Hacker | FF4: Field Surgeon | FG4: First Aid | FH4: Fix It Good | FI4: Good With Salt | FJ4: Gunsmith | FK4: Hacker | FL4: Licensed Plumber | FM4: Makeshift Warrior | FN4: Master Hacker | FO4: Nerd Rage! | FP4: Pharmacist | FQ4: Power Patcher | FR4: Power Smith | FS4: Power User | FT4: Pyro-Technician | FU4: Robotics Expert | FV4: Science! | FW4: Scrapper | FX4: Stabilized | FY4: Stable Tools | FZ4: Weapon Artisan | GA4: White Knight | GB4: Bomb Scientist | GC4: Mad Scientist | GD4: Rad Specialist | GE4: Science Monster | GF4: Action Boy | GG4: Action Girl | GH4: Adrenaline | GI4: Ammosmith | GJ4: Born Survivor | GK4: Covert Operative | GL4: Dead Man Sprinting | GM4: Dodgy | GN4: Enforcer | GO4: Escape Artist | GP4: Evasive | GQ4: Goat Legs | GR4: Guerrilla | GS4: Guerrilla Expert | GT4: Guerrilla Master | GU4: Gun Fu | GV4: Gun Runner | GW4: Gunslinger | GX4: Gunslinger Expert | GY4: Gunslinger Master | GZ4: Home Defense | HA4: Light Footed | HB4: Marathoner | HC4: Mister Sandman | HD4: Modern Renegade | HE4: Moving Target | HF4: Ninja | HG4: Packin' Light | HH4: Secret Agent | HI4: Sneak | HJ4: Action Ghoul | HK4: Gun Tricks | HL4: Hyper Reflexes | HM4: Jaguar Speed | HN4: Better Criticals | HO4: Bloody Mess | HP4: Can Do! | HQ4: Cap Collector | HR4: Class Freak | HS4: Critical Savvy | HT4: Dry Nurse | HU4: Four Leaf Clover | HV4: Grim Reaper's Sprint | HW4: Junk Shield | HX4: Last Laugh | HY4: Luck of the Draw | HZ4: Lucky Break | IA4: Mysterious Savior | IB4: Mysterious Stranger | IC4: Mystery Meat | ID4: One Gun Army | IE4: Pharma Farma | IF4: Psychopath | IG4: Quick Hands | IH4: Ricochet | II4: Scrounger | IJ4: Serendipity | IK4: Storm Chaser | IL4: Super Duper | IM4: Woodchucker | IN4: Battle-Genes | IO4: Faulty Spots | IP4: Glowing Criticals | IQ4: Wild West Hands
A5: Atom - Ghoul VATS/Onslaught/Cripple | B5: 9 | C5: 11 | D5: 13 | E5: 6 | F5: 12 | G5: 15 | H5: 15 | I5: 1 | J5: 0 | K5: 0 | L5: 0 | M5: 0 | N5: 1 | O5: 0 | P5: 0 | Q5: 0 | R5: 3 | S5: 0 | T5: 0 | U5: 0 | V5: 0 | W5: 0 | X5: 0 | Y5: 0 | Z5: 0 | AA5: 0 | AB5: 0 | AC5: 0 | AD5: 0 | AE5: 0 | AF5: 1 | AG5: 0 | AH5: 0 | AI5: 0 | AJ5: 0 | AK5: 0 | AL5: 0 | AM5: 0 | AN5: 0 | AO5: 0 | AP5: 0 | AQ5: 0 | AR5: 1 | AS5: 0 | AT5: 1 | AU5: 0 | AV5: 0 | AW5: 0 | AX5: 0 | AY5: 0 | AZ5: 1 | BA5: 0 | BB5: 0 | BC5: 0 | BD5: 0 | BE5: 0 | BF5: 0 | BG5: 0 | BH5: 0 | BI5: 0 | BJ5: 0 | BK5: 0 | BL5: 0 | BM5: 0 | BN5: 0 | BO5: 0 | BP5: 1 | BQ5: 0 | BR5: 0 | BS5: 0 | BT5: 0 | BU5: 0 | BV5: 0 | BW5: 0 | BX5: 0 | BY5: 2 | BZ5: 1 | CA5: 0 | CB5: 0 | CC5: 0 | CD5: 0 | CE5: 1 | CF5: 0 | CG5: 0 | CH5: 0 | CI5: 0 | CJ5: 0 | CK5: 0 | CL5: 0 | CM5: 0 | CN5: 0 | CO5: 0 | CP5: 0 | CQ5: 0 | CR5: 1 | CS5: 0 | CT5: 0 | CU5: 0 | CV5: 1 | CW5: 0 | CX5: 1 | CY5: 0 | CZ5: 0 | DA5: 0 | DB5: 0 | DC5: 0 | DD5: 0 | DE5: 0 | DF5: 0 | DG5: 0 | DH5: 0 | DI5: 1 | DJ5: 0 | DK5: 0 | DL5: 0 | DM5: 0 | DN5: 0 | DO5: 0 | DP5: 3 | DQ5: 3 | DR5: 0 | DS5: 0 | DT5: 0 | DU5: 0 | DV5: 0 | DW5: 0 | DX5: 0 | DY5: 0 | DZ5: 0 | EA5: 0 | EB5: 0 | EC5: 0 | ED5: 0 | EE5: 0 | EF5: 0 | EG5: 0 | EH5: 0 | EI5: 0 | EJ5: 0 | EK5: 0 | EL5: 0 | EM5: 0 | EN5: 1 | EO5: 0 | EP5: 0 | EQ5: 1 | ER5: 0 | ES5: 0 | ET5: 0 | EU5: 0 | EV5: 0 | EW5: 3 | EX5: 0 | EY5: 2 | EZ5: 0 | FA5: 0 | FB5: 1 | FC5: 0 | FD5: 0 | FE5: 0 | FF5: 0 | FG5: 0 | FH5: 0 | FI5: 2 | FJ5: 2 | FK5: 0 | FL5: 0 | FM5: 0 | FN5: 0 | FO5: 0 | FP5: 0 | FQ5: 0 | FR5: 0 | FS5: 0 | FT5: 0 | FU5: 0 | FV5: 0 | FW5: 1 | FX5: 0 | FY5: 0 | FZ5: 0 | GA5: 0 | GB5: 0 | GC5: 3 | GD5: 0 | GE5: 0 | GF5: 0 | GG5: 0 | GH5: 1 | GI5: 0 | GJ5: 0 | GK5: 0 | GL5: 0 | GM5: 0 | GN5: 2 | GO5: 0 | GP5: 0 | GQ5: 0 | GR5: 0 | GS5: 1 | GT5: 1 | GU5: 1 | GV5: 0 | GW5: 3 | GX5: 1 | GY5: 0 | GZ5: 0 | HA5: 0 | HB5: 0 | HC5: 0 | HD5: 0 | HE5: 0 | HF5: 0 | HG5: 0 | HH5: 0 | HI5: 0 | HJ5: 0 | HK5: 0 | HL5: 0 | HM5: 0 | HN5: 3 | HO5: 0 | HP5: 0 | HQ5: 0 | HR5: 0 | HS5: 3 | HT5: 0 | HU5: 1 | HV5: 0 | HW5: 1 | HX5: 0 | HY5: 0 | HZ5: 0 | IA5: 0 | IB5: 0 | IC5: 0 | ID5: 0 | IE5: 0 | IF5: 0 | IG5: 0 | IH5: 1 | II5: 0 | IJ5: 0 | IK5: 0 | IL5: 0 | IM5: 0 | IN5: 0 | IO5: 1 | IP5: 1 | IQ5: 3
A6: Blank / Custom | B6: 1 | C6: 1 | D6: 1 | E6: 1 | F6: 1 | G6: 1 | H6: 1 | I6: 0 | J6: 0 | K6: 0 | L6: 0 | M6: 0 | N6: 0 | O6: 0 | P6: 0 | Q6: 0 | R6: 0 | S6: 0 | T6: 0 | U6: 0 | V6: 0 | W6: 0 | X6: 0 | Y6: 0 | Z6: 0 | AA6: 0 | AB6: 0 | AC6: 0 | AD6: 0 | AE6: 0 | AF6: 0 | AG6: 0 | AH6: 0 | AI6: 0 | AJ6: 0 | AK6: 0 | AL6: 0 | AM6: 0 | AN6: 0 | AO6: 0 | AP6: 0 | AQ6: 0 | AR6: 0 | AS6: 0 | AT6: 0 | AU6: 0 | AV6: 0 | AW6: 0 | AX6: 0 | AY6: 0 | AZ6: 0 | BA6: 0 | BB6: 0 | BC6: 0 | BD6: 0 | BE6: 0 | BF6: 0 | BG6: 0 | BH6: 0 | BI6: 0 | BJ6: 0 | BK6: 0 | BL6: 0 | BM6: 0 | BN6: 0 | BO6: 0 | BP6: 0 | BQ6: 0 | BR6: 0 | BS6: 0 | BT6: 0 | BU6: 0 | BV6: 0 | BW6: 0 | BX6: 0 | BY6: 0 | BZ6: 0 | CA6: 0 | CB6: 0 | CC6: 0 | CD6: 0 | CE6: 0 | CF6: 0 | CG6: 0 | CH6: 0 | CI6: 0 | CJ6: 0 | CK6: 0 | CL6: 0 | CM6: 0 | CN6: 0 | CO6: 0 | CP6: 0 | CQ6: 0 | CR6: 0 | CS6: 0 | CT6: 0 | CU6: 0 | CV6: 0 | CW6: 0 | CX6: 0 | CY6: 0 | CZ6: 0 | DA6: 0 | DB6: 0 | DC6: 0 | DD6: 0 | DE6: 0 | DF6: 0 | DG6: 0 | DH6: 0 | DI6: 0 | DJ6: 0 | DK6: 0 | DL6: 0 | DM6: 0 | DN6: 0 | DO6: 0 | DP6: 0 | DQ6: 0 | DR6: 0 | DS6: 0 | DT6: 0 | DU6: 0 | DV6: 0 | DW6: 0 | DX6: 0 | DY6: 0 | DZ6: 0 | EA6: 0 | EB6: 0 | EC6: 0 | ED6: 0 | EE6: 0 | EF6: 0 | EG6: 0 | EH6: 0 | EI6: 0 | EJ6: 0 | EK6: 0 | EL6: 0 | EM6: 0 | EN6: 0 | EO6: 0 | EP6: 0 | EQ6: 0 | ER6: 0 | ES6: 0 | ET6: 0 | EU6: 0 | EV6: 0 | EW6: 0 | EX6: 0 | EY6: 0 | EZ6: 0 | FA6: 0 | FB6: 0 | FC6: 0 | FD6: 0 | FE6: 0 | FF6: 0 | FG6: 0 | FH6: 0 | FI6: 0 | FJ6: 0 | FK6: 0 | FL6: 0 | FM6: 0 | FN6: 0 | FO6: 0 | FP6: 0 | FQ6: 0 | FR6: 0 | FS6: 0 | FT6: 0 | FU6: 0 | FV6: 0 | FW6: 0 | FX6: 0 | FY6: 0 | FZ6: 0 | GA6: 0 | GB6: 0 | GC6: 0 | GD6: 0 | GE6: 0 | GF6: 0 | GG6: 0 | GH6: 0 | GI6: 0 | GJ6: 0 | GK6: 0 | GL6: 0 | GM6: 0 | GN6: 0 | GO6: 0 | GP6: 0 | GQ6: 0 | GR6: 0 | GS6: 0 | GT6: 0 | GU6: 0 | GV6: 0 | GW6: 0 | GX6: 0 | GY6: 0 | GZ6: 0 | HA6: 0 | HB6: 0 | HC6: 0 | HD6: 0 | HE6: 0 | HF6: 0 | HG6: 0 | HH6: 0 | HI6: 0 | HJ6: 0 | HK6: 0 | HL6: 0 | HM6: 0 | HN6: 0 | HO6: 0 | HP6: 0 | HQ6: 0 | HR6: 0 | HS6: 0 | HT6: 0 | HU6: 0 | HV6: 0 | HW6: 0 | HX6: 0 | HY6: 0 | HZ6: 0 | IA6: 0 | IB6: 0 | IC6: 0 | ID6: 0 | IE6: 0 | IF6: 0 | IG6: 0 | IH6: 0 | II6: 0 | IJ6: 0 | IK6: 0 | IL6: 0 | IM6: 0 | IN6: 0 | IO6: 0 | IP6: 0 | IQ6: 0
